Workbook

Sheet Start Here
A1: PakFreight Star Builder — Week 3 Activity
A2: Data Warehousing & Business Intelligence · Week 3 — Fact & Dimension Tables · CLO2 · The Superior University, Lahore
A4: THE SITUATION
A5: Week 2 ended with one flat table: Shipments_Unified, 34 rows, 578,650 kg, PKR 4,808,000. It answers simple questions and fails at every interesting one — there is no province column, no month column, Karachi is spelled five different ways, and nothing in it remembers what a route used to be called. Today you split it into one fact table and five dimensions, and the totals must not move by a single kilogram.
A7: HOW TO WORK
A8: • Teams of 3. Name one person each: Modeller (owns the grain), Conformer (owns DimCity), Reconciler (owns T7 and has veto power over 'it looks fine').
A9: • Do the tasks in order. T6 cannot be filled in before T4 and T5 exist — that is not a quirk of this workbook, it is why dimensions are always loaded before facts.
A10: • Type only in CREAM cells. GREY cells are source data as received — never edit them.
A11: • T7 marks itself. Every '✘ fix' means something earlier is still wrong. Do not submit with a red cell and a hopeful note.
A12: • Save as W3_Star_<team number>.xlsx and submit on the LMS before Week 4, with the Power BI file described in PakFreight_W3_PowerBI_Lab_Guide.md.
A14: THE SEVEN TASKS
A15: # | B15: Task | C15: What you produce | D15: 180-min class | E15: 120-min class | F15: Where it comes from in the lecture
A16: T1 | B16: Classify every column | C16: Fact, dimension attribute, degenerate or drop | D16: 10 | E16: 8 | F16: Slides 9-17 · what belongs where
A17: T2 | B17: Declare the grain | C17: One sentence, no 'and' — for PakFreight and 4 new processes | D17: 12 | E17: 10 | F17: Slides 19-24 · Kimball's four steps
A18: T3 | B18: Additivity audit | C18: Additive, semi-additive, non-additive — and prove the ratio trap | D18: 10 | E18: 7 | F18: Slide 10 · 8.06 vs 8.31
A19: T4 | B19: Build DimCity | C19: Conform 23 raw location strings into 14 cities, mint the keys | D19: 20 | E19: 15 | F19: Slides 11, 30, 43 · surrogate keys
A20: T5 | B20: Build the other four dimensions | C20: DimRoute, DimMode, DimStatus, DimDate | D20: 20 | E20: 15 | F20: Slides 31-34, 38, 44
A21: T6 | B21: Build FactShipment | C21: Swap every text column for an integer key | D21: 15 | E21: 12 | F21: Slides 9, 44 · merge on the key only
A22: T7 | B22: Reconcile | C22: Thirteen checks. All thirteen must read 'pass' | D22: 8 | E22: 8 | F22: Slide 46 · validate before you trust
C23: Total minutes | D23: 95 | E23: 75
A25: COLOUR LEGEND
B26: You type here
B27: Source data — do not edit
B28: ✔ pass — check satisfied
B29: ✘ fix — go back and correct it
B30: Model answer (teacher key only)
A32: THE GRAIN CONTRACT — WRITE IT ONCE, OBEY IT EVERYWHERE
B33: Decision | C33: Your answer (T2 fills this in) | F33: Why it matters
B34: Business process | C34: Freight shipment movement | F34: Step 1 of Kimball's four steps — pick a process, not a department.
B35: Grain (one row = ?) | F35: Step 2. If your sentence needs the word 'and', you have two fact tables.
B36: Fact table type | F36: Transaction, periodic snapshot or accumulating snapshot.
B37: Dimensions | F37: Step 3 — and they must follow from the grain, not from your imagination.
B38: Measures | F38: Step 4 — additive wherever you can manage it.

Sheet Shipments_Unified
A1: Shipments_Unified — the Week 2 output
A2: 34 rows · 578,650 kg · PKR 4,808,000. Grey means source data: read it, point formulas at it, never edit it. This whole sheet becomes FactShipment in T6.
A4: ShipmentID | B4: ShipDate | C4: Origin | D4: Destination | E4: WeightKG | F4: CostPKR | G4: Status | H4: SourceSystem
A5: MR-1001 | B5: 46054 | C5: Karachi Port | D5: Lahore Dry Port | E5: 18000 | F5: 142000 | G5: Delivered | H5: Marine
A6: MR-1002 | B6: 46055 | C6: Port Qasim | D6: Faisalabad Dry Port | E6: 22500 | F6: 171000 | G6: Delivered | H6: Marine
A7: MR-1003 | B7: 46056 | C7: Karachi Port | D7: Lahore Dry Port | E7: 15000 | F7: 119000 | G7: In Transit | H7: Marine
A8: MR-1004 | B8: 46057 | C8: Gwadar Port | D8: Quetta | E8: 20000 | F8: 188000 | G8: Delivered | H8: Marine
A9: MR-1005 | B9: 46058 | C9: Port Qasim | D9: Multan | E9: 16500 | F9: 128000 | G9: Delivered | H9: Marine
A10: MR-1006 | B10: 46059 | C10: Karachi Port | D10: Sialkot Dry Port | E10: 19000 | F10: 154000 | G10: Delayed | H10: Marine
A11: MR-1007 | B11: 46060 | C11: Port Qasim | D11: Lahore Dry Port | E11: 14000 | F11: 109000 | G11: Delivered | H11: Marine
A12: MR-1008 | B12: 46062 | C12: Karachi Port | D12: Peshawar | E12: 21000 | F12: 197000 | G12: In Transit | H12: Marine
A13: MR-1009 | B13: 46063 | C13: Gwadar Port | D13: Karachi Cantt | E13: 17500 | F13: 98000 | G13: Delivered | H13: Marine
A14: MR-1010 | B14: 46064 | C14: Port Qasim | D14: Islamabad Dry Port | E14: 15500 | F14: 139000 | G14: Delivered | H14: Marine
A15: MR-1011 | B15: 46065 | C15: Karachi Port | D15: Hyderabad | E15: 13500 | F15: 61000 | G15: In Transit | H15: Marine
A16: MR-1012 | B16: 46066 | C16: Port Qasim | D16: Lahore Dry Port | E16: 14000 | F16: 112000 | G16: Delivered | H16: Marine
... A38: RD-512 | B38: 46066 | C38: Rawalpindi | D38: Abbottabad | E38: 5800 | F38: 45000 | G38: Delivered | H38: Road
D39: TOTAL | E39: =SUM(E5:E38) -> 578650 | F39: =SUM(F5:F38) -> 4808000
A41: Count the distinct dates in column B. There are 12 — not 28. February 2026 has 28 days and PakFreight dispatched nothing on 16 of them. Any 'average per day' computed from this sheet divides by the wrong number, silently. That is what DimDate in T5 is for.

Sheet T1 Classify
A1: T1 · Fact, Dimension, Degenerate or Drop?
A2: PakFreight's operations team wants twelve more columns added to the warehouse. For each one write F (fact / measure), D (dimension attribute), DD (degenerate dimension) or X (belongs in neither), name the table it should live in, and defend it in one line. Four of the twelve are deliberately tricky.
A4: # | B4: Column the team asked for | C4: F / D / DD / X | D4: Which table does it live in? | E4: Your one-line justification
A5: 1 | B5: Driver_Name | C5: D | D5: DimDriver | E5: Descriptive text about who performed the delivery belongs in a dimension table.
A6: 2 | B6: Days_Late | C6: F | D6: FactShipment | E6: A numerical performance measurement of delivery delay that can be aggregated.
A7: 3 | B7: Invoice_Number | C7: DD | D7: FactShipment | E7: An operational tracking identifier stored directly in the fact table without its own dimension.
A8: 4 | B8: Discount_Percent | C8: X | D8: None (Drop) | E8: Percentages cannot be added across rows; store raw currency/amounts instead.
A9: 5 | B9: Truck_Registration_No | C9: D | D9: DimTruck | E9: Looks like a key, but it describes a physical truck entity containing multiple attributes.
A10: 6 | B10: Container_Count | C10: F | D10: FactShipment | E10: An additive numeric measure representing the physical count of containers shipped.
A11: 7 | B11: Customer_Credit_Rating | C11: D | D11: DimCustomer | E11: Descriptive customer attribute categorizing risk profile, stored in the customer dimension.
A12: 8 | B12: Cost_Per_Tonne_KM | C12: X | D12: None (Drop) | E12: A pre-calculated unit rate/ratio; rates are only valid at their original level.
A13: 9 | B13: Row_Inserted_Timestamp | C13: F | D13: FactShipment | E13: Technical ETL audit metadata stored directly in the fact table for data lineage and pipeline monitoring..
A14: 10 | B14: Fuel_Surcharge_PKR | C14: F | D14: FactShipment | E14: A monetary cost value that is fully additive and safe to sum as a fact.
A15: 11 | B15: Weather_Condition | C15: D | D15: DimWeather | E15: Descriptive environmental context characterizing the delivery day.
A16: 12 | B16: Is_Hazardous_Cargo | C16: DD | D16: FactShipment | E16: Low-cardinality boolean flag stored directly in the fact table as a degenerate dimension to avoid unnecessary dimension bloat.
B17: Answered so far | C17: =COUNTA(C5:C16)&" / 12" -> 12 / 12
A19: DEFEND YOUR ANSWERS — THE THREE QUESTIONS WE WILL ASK
A20: Which of your X answers would a real analyst fight you over, and what is their best argument? | C20: Cost_Per_Tonne_KM. Analysts will argue that keeping this pre-calculated metric saves query time and ensures everyone uses the exact same efficiency formula.
A22: Name one column you marked D that deserves its own dimension table, and three attributes it would carry. | C22: Truck_Registration_No. It deserves DimTruck, which would carry: Truck_Model, Max_Weight_Capacity, and Fuel_Type.
A24: If Days_Late is a fact, which dimension supplies the deadline it is measured against? | C24: DimDate (via the scheduled or planned delivery date attribute).
A27: Marking: 6 marks for the twelve verdicts (half a mark each), 3 marks for the justifications, 3 marks for the three questions. A wrong verdict with a sharp justification scores more than a right verdict with none — the reasoning is the skill.

Sheet T2 Grain
A1: T2 · Declare the Grain
A2: The single most consequential sentence in warehouse design. Write it for PakFreight, then for four processes PakFreight wants to add next. Use the template: 'One row per …'. If your sentence needs the word 'and', you have described two fact tables.
A4: PART A · THE PAKFREIGHT GRAIN STATEMENT
B5: One row of FactShipment represents… | C5: One row per shipment leg. | F5: =IF(C5="","— not written yet",IF(ISNUMBER(SEARCH(" and ",C5)),"✘ contains 'and' — that is two fact tables","✔ no 'and' — one grain")) -> ✔ no 'and' — one grain
A6: Why 'leg' and not 'shipment'? MR-1009 moves Gwadar → Karachi and RD-508 moves Quetta → Karachi. If a single customer consignment is later carried marine-then-road, 'one row per shipment' becomes ambiguous the day PakFreight sells multi-modal freight — and the grain you declare today is the one the CFO's 2027 reports will be built on.
A8: PART B · FOUR NEW PROCESSES — GRAIN, DIMENSIONS, MEASURES, FACT TYPE
A9: # | B9: Business process | C9: Grain sentence (one row per …) | D9: Dimensions it implies | E9: Two measures | F9: Fact table type + why
A10: 1 | B10: Fuel purchases at PakFreight depots | C10: One row per depot fuel transaction. | D10: DimDepot, DimVehicle, DimDriver, DimDate | E10: LitersPurchased, TotalFuelCost | F10: Transaction fact table, because an event occurs at a specific point in time whenever fuel is purchased.
B11: Hint: Is the grain one fuel purchase, one litre, or one truck per week?
A12: 2 | B12: Driver duty hours and rest compliance | C12: One row per driver daily duty shift. | D12: DimDriver, DimVehicle, DimDate | E12: DutyHours, RestHours | F12: Transaction fact table, because it logs each individual daily duty/shift event completed by a driver.
B13: Hint: Regulators care about a rolling 14-day window. Does that change the grain, or only the measures?
A14: 3 | B14: Customer complaints about late delivery | C14: One row per customer complaint. | D14: DimCustomer, DimDate, DimComplaintType, plus BridgeComplaintShipment (Bridge Table) | E14: ComplaintCount (or 1), ResolutionTimeHours | F14: Transaction fact table, because each complaint logged is an individual operational event. Needs a bridge table because one complaint can link to multiple shipments.
B15: Hint: One complaint can reference several shipments. Where does that relationship live?
A16: 4 | B16: Daily warehouse stock levels at Lahore Dry Port | C16: One row per product per day per warehouse location. | D16: DimProduct, DimLocation, DimDate | E16: QuantityOnHand, ReservedQuantity | F16: Periodic snapshot fact table, because stock levels are captured at regular time intervals (daily) even when no transaction occurs.
B17: Hint: Nothing 'happens' on a quiet day — but you still need a number. Which fact shape is this?
A19: PART C · THE GRAIN THAT WENT WRONG — A 20-SECOND CASE
B20: A PakFreight analyst needs cost per customer, so he adds CustomerName to FactShipment. Two shipments on RD-501 are billed to two customers who split the truck. He cannot choose, so he duplicates the row — once per customer. The table now has 35 rows, total weight reads 585,150 kg, and every weight report in the company is overstated by 6,500 kg forever. In one line each: (a) what rule did he break? (b) what should he have built instead? (c) which of T7's twelve checks would have caught it?
B23: (a) He broke the rule: "Never put descriptive text in a fact table" and violated the table's grain by duplicating rows to handle multiple entities. (b) He should have kept DimCustomer separate and built a Bridge Table between shipments and customers to handle the many-to-many splitting without duplicating fact rows. (c) The Reconciliation / Total Weight Check (which checks that overall totals do not shift or overstate).
A26: Marking, 12 marks: Part A grain sentence 3 · Part B 1.5 per process (grain 0.75, dimensions 0.5, measures 0.25) · Part C 3 · bonus 1 for spotting that #4 is a periodic snapshot and #3 needs a bridge table. A sentence containing 'and' loses the grain mark however good the rest is.

Sheet T3 Additivity
A1: T3 · Additivity Audit — and the ratio that lies by 3%
A2: A measure is only useful once you know which dimensions you may add it across. Classify ten measures, then prove the ratio trap on PakFreight's own 34 rows.
A4: # | B4: Candidate measure | C4: Additive / Semi / Non | D4: Safe to SUM across time? | E4: What should you store instead? | F4: Notes / your reasoning
A5: 1 | B5: WeightKG | C5: Additive | D5: Yes | E5: WeightKG (store as-is) | F5: Can be aggregated across any dimension and time period without loss of meaning.
A6: 2 | B6: FreightCostPKR | C6: Additive | D6: Yes | E6: FreightCostPKR (store as-is) | F6: Financial amounts are fully additive across both entities and time.
A7: 3 | B7: ShipmentCount (=1) | C7: Additive | D7: Yes | E7: ShipmentCount | F7: Acting as a counter (1 per row), it can be freely summed to get total transaction volume.
A8: 4 | B8: TrucksAvailable at a depot | C8: Semi-additive | D8: No | E8: TrucksAvailable (stock snapshot) | F8: Stock levels can be added across depots at a point in time, but cannot be summed across days.
A9: 5 | B9: WarehouseStockKG | C9: Semi-additive | D9: No | E9: WarehouseStockKG (inventory balance) | F9: Similar to truck availability; valid across locations for a single moment, but invalid to sum across time.
A10: 6 | B10: CostPerKG | C10: Non-additive | D10: No | E10: FreightCostPKR and WeightKG | F10: A ratio/average. Summing rates across rows creates a mathematically invalid percentage/rate.
A11: 7 | B11: OnTimePercent | C11: Non-additive | D11: No | E11: OnTimeCount and TotalShipments | F11: Percentages cannot be averaged across shipments or time; store component counts instead.
A12: 8 | B12: TruckUtilisationRate | C12: Non-additive | D12: No | E12: UsedCapacity and TotalCapacity | F12: Another utilization ratio that breaks if summed directly across trips.
A13: 9 | B13: Days_Late | C13: Additive | D13: Yes | E13: Days_Late (can be summed across shipments) | F13: Represents total delay duration, which can be safely summed and averaged later.
A14: 10 | B14: AverageWeightPerShipment | C14: Non-additive | D14: No | E14: WeightKG and ShipmentCount | F14: Stored pre-calculated averages destroy underlying granularity and cannot be re-rolled up.
A16: THE PROOF · AVERAGE OF A RATIO vs RATIO OF TWO SUMS — SAME 34 ROWS, TWO DIFFERENT ANSWERS
B17: WRONG — average the per-row ratio | C17: =SUMPRODUCT(Shipments_Unified!F5:F38/Shipments_Unified!E5:E38)/34 -> 8.060355 | D17: What AVERAGE(Cost/Weight) gives you, and what a careless DAX measure gives you.
B18: RIGHT — divide the two sums | C18: =SUM(Shipments_Unified!F5:F38)/SUM(Shipments_Unified!E5:E38) -> 8.3089951 | D18: What DIVIDE(SUM(Cost), SUM(Weight)) gives you. The only version that is correct at every level.
B19: The gap, in PKR per kg | C19: =C18-C17 -> 0.24864011 | D19: Small enough that nobody notices. On PakFreight's real annual volume it is tens of millions.
B20: The gap, as a percentage | C20: =(C18-C17)/C17 -> 0.03084729 | D20: No error is raised. No cell turns red. The number is simply wrong.
B21: Expected: 8.0604 (wrong) and 8.3090 (right)
B22: Why it happens: Row-level averaging treats every shipment equally regardless of its size, whereas dividing the sums weights every kilogram correctly.
A23: ANSWER IN ONE LINE EACH
B24: Which of the two numbers above would you put on a board slide, and what exactly does the other one measure? | D24: Put 8.3090 (the ratio of sums) on the board slide because it represents the true overall cost per kg. The other number (8.0604) measures the unweighted average of individual trip ratios rather than true financial reality.
B26: PakFreight's CFO asks for 'average cost per kg by province'. Write the rule you will follow so the provincial numbers still roll up to the national one. | D26: Store FreightCostPKR and WeightKG separately, and calculate the ratio dynamically using SUM(FreightCostPKR) / SUM(WeightKG) at any geographic or time level
B28: Name the one measure in the table above whose correct answer is 'delete the column', and say why a stored average can never be fixed later. | D28: AverageWeightPerShipment. Once you store a pre-calculated average, the underlying individual weights and counts are lost, making it impossible to correctly recalculate or roll up the data for different groups later.
A31: Marking, 10 marks: classification 5 (half a mark per row) · 'store instead' column 2 · the three questions 3. Full marks on question 1 require naming what 8.06 actually measures — 'it is wrong' is not an answer.

Sheet T4 DimCity
A1: T4 · Conform 23 Location Strings into 14 Cities
A2: This is the editorial act of dimensional modelling, and it is yours. Block 1: decide what each raw string really is. Block 2: build the dimension, one row per real-world city, with a surrogate key you mint yourself.
A4: BLOCK 1 · THE CONFORMING MAP — 23 RAW STRINGS, EXACTLY AS THE SOURCE SYSTEMS WROTE THEM
A5: # | B5: Raw location string (grey — do not edit) | C5: Conformed CityName | D5: Province | E5: Region | F5: Port city? | G5: Facility type | I5: CityKey | J5: CityName | K5: Province | L5: Region | M5: Port? | N5: FacilityType | O5: SourceAliases (which raw strings map here)
A6: 1 | B6: Karachi Port | C6: Karachi | D6: Sindh | E6: South | F6: Yes | G6: Seaport | I6: 1 | J6: Lahore | K6: Punjab | L6: Central | M6: Yes | N6: Dry Port | O6: LHE, Mughalpura Dry Port, Prem Nagar Dry Port, NLC Thokar
A7: 2 | B7: Port Qasim | C7: Karachi | D7: Sindh | E7: South | F7: Yes | G7: Seaport | I7: 2 | J7: Islamabad | K7: Islamabad ICT | L7: North | M7: Yes | N7: Dry Port | O7: ISB, Islamabad Dry Port, Margalla Freight Depot
A8: 3 | B8: Gwadar Port | C8: Gwadar | D8: Balochistan | E8: Southwestern | F8: Yes | G8: Seaport | I8: 3 | J8: Karachi | K8: Sindh | L8: South | M8: Yes | N8: Seaport | O8: KHI, Karachi Port, Port Qasim, KPT
A9: 4 | B9: Karachi Cantt | C9: Karachi | D9: Sindh | E9: South | F9: Yes | G9: Seaport | I9: 4 | J9: Hyderabad | K9: Sindh | L9: South | M9: Yes | N9: Dry Port | O9: HDD, Hyderabad Dry Port, NLC Hyderabad
A10: 5 | B10: Pipri Marshalling Yard | C10: Karachi | D10: Sindh | E10: South | F10: Yes | G10: Seaport | I10: 5 | J10: Faisalabad | K10: Punjab | L10: Central | M10: Yes | N10: Dry Port | O10: LYP, Faisalabad Dry Port Trust (FDPT)
A11: 6 | B11: Lahore | C11: Lahore | D11: Punjab | E11: Central | F11: Yes | G11: Dry Port | I11: 6 | J11: Multan | K11: Punjab | L11: South | M11: Yes | N11: Dry Port | O11: MUX, Multan Dry Port, South Punjab Dry Port
A12: 7 | B12: Karachi | C12: Karachi | D12: Sindh | E12: South | F12: Yes | G12: Seaport | I12: 7 | J12: Peshawar | K12: Khyber Pakhtunkhwa | L12: North-Western | M12: Yes | N12: Dry Port | O12: PEW, Peshawar Dry Port
A13: 8 | B13: Multan | C13: Multan | D13: Punjab | E13: South | F13: Yes | G13: Dry Port | I13: 8 | J13: Sukkur | K13: Sindh | L13: South | M13: No | N13: City Hub | O13: SKZ, Sukkur
A14: 9 | B14: Islamabad | C14: Islamabad | D14: Islamabad ICT | E14: North | F14: Yes | G14: Dry Port | I14: 9 | J14: Sialkot | K14: Punjab | L14: North-Eastern | M14: Yes | N14: Dry Port | O14: SKT, Sialkot Dry Port Trust (SDPT), Sambrial Dry Port
A15: 10 | B15: Quetta | C15: Quetta | D15: Balochistan | E15: West | F15: Yes | G15: Dry Port | I15: 10 | J15: Quetta | K15: Balochistan | L15: West | M15: Yes | N15: Dry Port | O15: UET, Quetta Dry Port, NLC Quetta
A16: 11 | B16: Faisalabad | C16: Faisalabad | D16: Punjab | E16: Central | F16: Yes | G16: Dry Port | I16: 11 | J16: Gujranwala | K16: Punjab | L16: Central | M16: No | N16: City Hub | O16: GRW, Gujranwala
A17: 12 | B17: Rawalpindi | C17: Rawalpindi | D17: Punjab | E17: North | F17: Yes | G17: Dry Port | I17: 12 | J17: Rawalpindi | K17: Punjab | L17: North | M17: Yes | N17: Dry Port | O17: RWP, Rawalpindi Dry Port, PR Freight Terminal Rawalpindi
... A20: 15 | B20: Sialkot Dry Port | C20: Sialkot | D20: Punjab | E20: North-Eastern | F20: Yes | G20: Dry Port | I20: -1 | J20: Unknown | K20: Unknown | L20: Unknown | M20: Unknown | N20: Unknown | O20: Unknown
A21: 16 | B21: Peshawar | C21: Peshawar | D21: Khyber Pakhtunkhwa | E21: North-Western | F21: Yes | G21: Dry Port
A22: 17 | B22: Islamabad Dry Port | C22: Islamabad | D22: Islamabad ICT | E22: North | F22: Yes | G22: Dry Port
A23: 18 | B23: Hyderabad | C23: Hyderabad | D23: Sindh | E23: South | F23: Yes | G23: Dry Port
A24: 19 | B24: Peshawar Cantt | C24: Peshawar | D24: Khyber Pakhtunkhwa | E24: North-Western | F24: No | G24: Railway Station
A25: 20 | B25: Sukkur | C25: Sukkur | D25: Sindh | E25: South | F25: No | G25: City Hub
A26: 21 | B26: Sialkot | C26: Sialkot | D26: Punjab | E26: North-Eastern | F26: Yes | G26: Dry Port
A27: 22 | B27: Gujranwala | C27: Gujranwala | D27: Punjab | E27: Central | F27: No | G27: City Hub
A28: 23 | B28: Abbottabad | C28: Abbottabad | D28: Khyber Pakhtunkhwa | E28: North | F28: No | G28: City Hub
A30: SELF-CHECK · THESE THREE MUST ALL PASS BEFORE YOU START T5
C31: Check | D31: Expected | E31: Your result | F31: Pass?
C32: Distinct conformed city names in Block 1 | D32: 14 | E32: =SUMPRODUCT((C6:C28<>"")/COUNTIF(C6:C28,C6:C28&"")) -> 14 | F32: =IF(E32=D32,"✔ pass","✘ fix") -> ✔ pass | G32: If you get 15 or more you have left two spellings of one city apart. If 13 or fewer you have merged two genuinely different cities — check Islamabad against Rawalpindi.
C33: Raw strings that map to Karachi | D33: 5 | E33: =COUNTIF(C6:C28,"Karachi") -> 5 | F33: =IF(E33=D33,"✔ pass","✘ fix") -> ✔ pass | G33: Karachi Port, Port Qasim, Karachi Cantt, Pipri Marshalling Yard and plain Karachi are five facilities in one city. Merging them is the whole point; getting 2 means you kept the rail yards separate.
C34: Rows in DimCity, excluding the Unknown row | D34: 14 | E34: =COUNTIF(I6:I20,">0") -> 14 | F34: =IF(E34=D34,"✔ pass","✘ fix") -> ✔ pass | G34: Fourteen cities plus one reserved row with key -1. The -1 row is not optional — T6 needs somewhere to point when a future file arrives with a city nobody has mapped.
A36: THE JUDGEMENT CALL — ANSWER BEFORE YOU MOVE ON
B37: Pipri Marshalling Yard is 40 km from Karachi Cantt and is a separate railway facility. You merged it into Karachi. Name one business decision that choice quietly made for PakFreight? | G37: Merging Pipri into Karachi quietly decided that PakFreight cannot track fuel usage, transit delays, or operational costs specifically for Pipri, making Pipri's unique efficiency issues invisible to management.
B39: Islamabad is its own territory, not part of Punjab. What breaks in a provincial report if you map it to Punjab, and what breaks if you leave Province blank? | G39: Mapping Islamabad to Punjab artificially inflates Punjab’s revenue and tax totals, while leaving Province blank drops Islamabad from provincial summaries entirely or causes grouping errors in BI reports.
B41: A new file arrives next month with 'KHI Port Trust'. Walk through exactly what has to happen, in order, for it to appear correctly in a report? | G41: 1.Map Raw String in Conforming Map: Step 1. Add 'KHI Port Trust' to the Conforming Map table and assign its Conformed CityName as 'Karachi' (with Sindh, South, Port city = Yes). 2.Re-run ETL Pipeline: Step 2. Execute the ETL job so the pipeline looks up 'KHI Port Trust', finds its mapped city, and fetches the corresponding surrogate key from DimCity. 3.Load Fact Table and Refresh BI: Step 3. Insert the new shipment rows into FactShipment using Karachi's surrogate key and refresh the reporting dashboard. Verification: Verify success by checking that queries on FactShipment grouped by DimCity.CityName cleanly include the new shipments under Karachi without creating duplicate or unassigned rows.
A44: Marking, 20 marks: conforming map 8 · provinces and regions correct 4 · DimCity built with a reused -1 row 4 · the three judgement questions 4. Karachi must be CityKey 1 everywhere it appears for the rest of the workbook to reconcile.

Sheet T5 Other Dimensions
A1: T5 · DimRoute, DimMode, DimStatus, DimDate
A2: Four more dimensions. One of them contains a trap that the lecture slides walk straight past — find it in Block A before you fill anything in.
A4: BLOCK A · DIMROUTE — 20 ROWS. BUT THE RAW DATA HAS 30 DISTINCT PAIRS.
A5: The lab brief says: 'Keep Origin and Destination, Remove Duplicates → 20 rows.' Try it on Shipments_Unified and you get 30. Column I below lists all 30 raw pairs. Before you build anything: write down why the two numbers differ, and which operation has to happen first.
B7: Your answer: | C7: 1. Why the Two Numbers Differ (30 vs. 20): The Raw Data Has Variations: The raw shipping logs contain different text spellings, extra spaces, or specific facility names (for example, Karachi Port, Karachi Cantt, and Port Qasim). Why Duplication Fails: A computer doing a standard "Remove Duplicates" command looks for exact character matches. Because the text spellings are different, the computer thinks they are 30 completely different routes instead of grouping them together. 2. Which Operation Must Happen First: Location Conformance (Data Standardization): You must first map and clean all the messy raw location names so they point to their correct, standard city names (for example, turning all Karachi variations into just Karachi). Once the locations are standardized, running the Remove Duplicates command will correctly reduce the list to the true 20 unique routes
A9: # | B9: RouteKey | C9: OriginCityKey | D9: DestCityKey | E9: RouteName | F9: Corridor | G9: DistanceBand | I9: The 30 RAW origin → destination pairs (grey)
A10: 1 | B10: 1 | C10: 1 | D10: 2 | E10: Lahore -> Islamabad | F10: Central / Regional Corridor | G10: Medium Haul | I10: Karachi Port → Lahore Dry Port
A11: 2 | B11: 2 | C11: 3 | D11: 1 | E11: Karachi -> Lahore | F11: North-South Corridor | G11: Very Long Haul | I11: Port Qasim → Faisalabad Dry Port
A12: 3 | B12: 3 | C12: 6 | D12: 1 | E12: Multan -> Lahore | F12: Central / Regional Corridor | G12: Medium Haul | I12: Gwadar Port → Quetta
A13: 4 | B13: 4 | C13: 1 | D13: 5 | E13: Lahore -> Faisalabad | F13: Central / Regional Corridor | G13: Short Haul | I13: Port Qasim → Multan
A14: 5 | B14: 5 | C14: 3 | D14: 5 | E14: Karachi -> Faisalabad | F14: North-South Corridor | G14: Long Haul | I14: Karachi Port → Sialkot Dry Port
A15: 6 | B15: 6 | C15: 1 | D15: 9 | E15: Lahore -> Sialkot | F15: Central / Regional Corridor | G15: Short Haul | I15: Port Qasim → Lahore Dry Port
A16: 7 | B16: 7 | C16: 3 | D16: 9 | E16: Karachi -> Sialkot | F16: North-South Corridor | G16: Very Long Haul | I16: Karachi Port → Peshawar
A17: 8 | B17: 8 | C17: 10 | D17: 3 | E17: Quetta -> Karachi | F17: Western-Southern Corridor | G17: Long Haul | I17: Gwadar Port → Karachi Cantt
A18: 9 | B18: 9 | C18: 1 | D18: 11 | E18: Lahore -> Gujranwala | F18: Central / Regional Corridor | G18: Short Haul | I18: Port Qasim → Islamabad Dry Port
A19: 10 | B19: 10 | C19: 3 | D19: 4 | E19: Karachi -> Hyderabad | F19: Southern Coastal Corridor | G19: Short Haul | I19: Karachi Port → Hyderabad
A20: 11 | B20: 11 | C20: 3 | D20: 8 | E20: Karachi -> Sukkur | F20: North-South Corridor | G20: Long Haul | I20: Karachi Cantt → Lahore
A21: 12 | B21: 12 | C21: 3 | D21: 6 | E21: Karachi -> Multan | F21: North-South Corridor | G21: Long Haul | I21: Karachi Cantt → Rawalpindi
... A29: 20 | B29: 20 | C29: 3 | D29: 12 | E29: Karachi -> Rawalpindi | F29: North-South Corridor | G29: Very Long Haul | I29: Lahore → Islamabad
B30: -1 | C30: Unknown | D30: Unknown | E30: Unknown | F30: Unknown | G30: Unknown | I30: Karachi → Hyderabad
I31: Lahore → Faisalabad
I32: Multan → Lahore
I33: Islamabad → Peshawar
I34: Karachi → Sukkur
I35: Lahore → Sialkot
I36: Quetta → Karachi
I37: Faisalabad → Multan
I38: Lahore → Gujranwala
I39: Rawalpindi → Abbottabad
I40: 30 raw pairs → 20 conformed routes
B41: Check · distinct RouteName values | E41: =SUMPRODUCT((E10:E30<>"")/COUNTIF(E10:E30,E10:E30&"")) -> 21 | F41: 21 | G41: =IF(E41=F41,"✔ pass","✘ fix") -> ✔ pass | I41: 20 real routes + 1 Unknown row = 21 distinct names.
A43: BLOCK B · DIMMODE AND DIMSTATUS — TYPED BY HAND. THIS IS REFERENCE DATA, NOT SOURCE DATA.
B44: ModeKey | C44: ModeName | D44: Carrier | E44: TonnageClass | F44: CostProfile | G44: Containerised? | K44: StatusKey | L44: StatusName | M44: IsClosed | N44: IsException | O44: DisplayOrder
B45: 1 | C45: Marine | D45: PakFreight Shipping Ltd | E45: Heavy (10–25 t) | F45: Low cost / slow | G45: Yes | K45: 1 | L45: Delivered | M45: Yes | N45: No | O45: No
B46: 2 | C46: Rail | D46: Pakistan Railways Freight | E46: Bulk (25–35 t) | F46: Medium cost / medium | G46: Partial | K46: 2 | L46: In Transit | M46: No | N46: No | O46: No
B47: 3 | C47: Road | D47: PakFreight Trucking | E47: Light (5–8 t) | F47: High cost / fast | G47: No | K47: 3 | L47: Delayed | M47: No | N47: Yes | O47: Yes
B48: -1 | C48: Unknown | D48: Unknown | E48: Unknown | F48: Unknown | G48: Unknown | K48: -1 | L48: Unknown | M48: No | N48: Yes | O48: Yes
B49: Both tables carry a row with key -1 called Unknown. It is not decoration: in T6 every lookup is a LEFT join, and a row whose mode nobody recognises must land somewhere visible rather than disappear. A fact row pointing at Unknown is a bug you can count; a fact row silently dropped is a bug you discover in a board meeting.
A51: BLOCK C · DIMDATE — 28 ROWS FOR FEBRUARY 2026, INCLUDING THE QUIET DAYS
B52: DateKey | C52: FullDate | D52: Year | E52: Quarter | F52: MonthNumber | G52: MonthName | I52: DayOfWeek | K52: DayNumber | L52: DayName | M52: IsWeekend | N52: IsHoliday | O52: Shipments that day | P52: In fact table?
...

Sheet T6 FactShipment
A1: T6 · Build FactShipment — Swap Every Text Column for an Integer Key
A2: Left of the gap: Shipments_Unified exactly as Week 2 left it. Right of the gap: the fact table. Row 6 is worked for you — copy it down to row 39. The rule you must not break: no descriptive text crosses the gap.
A3: Row 6 is worked for you — copy J6:S6 down to row 39. Until T4 and T5 are filled in, every key in row 6 reads -1. That is not an error: it is the Unknown row doing its job, because IFERROR sends an unmatched lookup to key -1 instead of losing the fact row. Watch them turn into real keys as you complete the dimensions.
A4: SOURCE · grey, do not edit | J4: FACTSHIPMENT · six keys + one degenerate + three measures | U4: EXCEL-ONLY SCRATCH
A5: ShipmentID | B5: ShipDate | C5: Origin | D5: Destination | E5: Source | F5: Status | G5: WeightKG | H5: CostPKR | J5: DateKey | K5: OriginCityKey | L5: DestCityKey | M5: RouteKey | N5: ModeKey | O5: StatusKey | P5: ShipmentID | Q5: WeightKG | R5: FreightCostPKR | S5: Count | U5: OriginProvince | V5: ModeName
A6: MR-1001 | B6: 46054 | C6: Karachi Port | D6: Lahore Dry Port | E6: Marine | F6: Delivered | G6: 18000 | H6: 142000 | J6: 20260201 | K6: 3 | L6: 1 | M6: 1 | N6: 1 | O6: 1 | P6: MR-1001 | Q6: 18000 | R6: 142000 | S6: 1 | U6: {=IFERROR(INDEX('T4 DimCity'!$K$6:$K$20,MATCH(K6,'T4 DimCity'!$I$6:$I$20,0)),"?")} -> Sindh | V6: {=IFERROR(INDEX('T5 Other Dimensions'!$C$45:$C$48,MATCH(N6,'T5 Other Dimensions'!$B$45:$B$48,0)),"?")} -> Marine
A7: MR-1002 | B7: 46055 | C7: Port Qasim | D7: Faisalabad Dry Port | E7: Marine | F7: Delivered | G7: 22500 | H7: 171000 | J7: 20260202 | K7: 1 | L7: 2 | M7: 3 | N7: 3 | O7: 1 | P7: RD-501 | Q7: 6500 | R7: 58000 | S7: 1 | U7: {=IFERROR(INDEX('T4 DimCity'!$K$6:$K$20,MATCH(K7,'T4 DimCity'!$I$6:$I$20,0)),"?")} -> Punjab | V7: {=IFERROR(INDEX('T5 Other Dimensions'!$C$45:$C$48,MATCH(N7,'T5 Other Dimensions'!$B$45:$B$48,0)),"?")} -> Road
A8: MR-1003 | B8: 46056 | C8: Karachi Port | D8: Lahore Dry Port | E8: Marine | F8: In Transit | G8: 15000 | H8: 119000 | J8: 20260204 | K8: 6 | L8: 1 | M8: 6 | N8: 3 | O8: 1 | P8: RD-504 | Q8: 6900 | R8: 61000 | S8: 1 | U8: {=IFERROR(INDEX('T4 DimCity'!$K$6:$K$20,MATCH(K8,'T4 DimCity'!$I$6:$I$20,0)),"?")} -> Punjab | V8: {=IFERROR(INDEX('T5 Other Dimensions'!$C$45:$C$48,MATCH(N8,'T5 Other Dimensions'!$B$45:$B$48,0)),"?")} -> Road
A9: MR-1004 | B9: 46057 | C9: Gwadar Port | D9: Quetta | E9: Marine | F9: Delivered | G9: 20000 | H9: 188000 | J9: 20260207 | K9: 1 | L9: 9 | M9: 4 | N9: 3 | O9: 1 | P9: RD-507 | Q9: 5900 | R9: 39000 | S9: 1 | U9: {=IFERROR(INDEX('T4 DimCity'!$K$6:$K$20,MATCH(K9,'T4 DimCity'!$I$6:$I$20,0)),"?")} -> Punjab | V9: {=IFERROR(INDEX('T5 Other Dimensions'!$C$45:$C$48,MATCH(N9,'T5 Other Dimensions'!$B$45:$B$48,0)),"?")} -> Road
A10: MR-1005 | B10: 46058 | C10: Port Qasim | D10: Multan | E10: Marine | F10: Delivered | G10: 16500 | H10: 128000 | J10: 20260203 | K10: 1 | L10: 5 | M10: 8 | N10: 3 | O10: 2 | P10: RD-503 | Q10: 5800 | R10: 32000 | S10: 1 | U10: {=IFERROR(INDEX('T4 DimCity'!$K$6:$K$20,MATCH(K10,'T4 DimCity'!$I$6:$I$20,0)),"?")} -> Punjab | V10: {=IFERROR(INDEX('T5 Other Dimensions'!$C$45:$C$48,MATCH(N10,'T5 Other Dimensions'!$B$45:$B$48,0)),"?")} -> Road
A11: MR-1006 | B11: 46059 | C11: Karachi Port | D11: Sialkot Dry Port | E11: Marine | F11: Delayed | G11: 19000 | H11: 154000 | J11: 20260209 | K11: 10 | L11: 3 | M11: 9 | N11: 3 | O11: 2 | P11: RD-508 | Q11: 6600 | R11: 92000 | S11: 1 | U11: {=IFERROR(INDEX('T4 DimCity'!$K$6:$K$20,MATCH(K11,'T4 DimCity'!$I$6:$I$20,0)),"?")} -> Balochistan | V11: {=IFERROR(INDEX('T5 Other Dimensions'!$C$45:$C$48,MATCH(N11,'T5 Other Dimensions'!$B$45:$B$48,0)),"?")} -> Road
A12: MR-1007 | B12: 46060 | C12: Port Qasim | D12: Lahore Dry Port | E12: Marine | F12: Delivered | G12: 14000 | H12: 109000 | J12: 20260211 | K12: 1 | L12: 11 | M12: 10 | N12: 3 | O12: 1 | P12: RD-510 | Q12: 7000 | R12: 27000 | S12: 1 | U12: {=IFERROR(INDEX('T4 DimCity'!$K$6:$K$20,MATCH(K12,'T4 DimCity'!$I$6:$I$20,0)),"?")} -> Punjab | V12: {=IFERROR(INDEX('T5 Other Dimensions'!$C$45:$C$48,MATCH(N12,'T5 Other Dimensions'!$B$45:$B$48,0)),"?")} -> Road
A13: MR-1008 | B13: 46062 | C13: Karachi Port | D13: Peshawar | E13: Marine | F13: In Transit | G13: 21000 | H13: 197000 | J13: 20260202 | K13: 3 | L13: 4 | M13: 10 | N13: 3 | O13: 1 | P13: RD-502 | Q13: 7200 | R13: 41000 | S13: 1 | U13: {=IFERROR(INDEX('T4 DimCity'!$K$6:$K$20,MATCH(K13,'T4 DimCity'!$I$6:$I$20,0)),"?")} -> Sindh | V13: {=IFERROR(INDEX('T5 Other Dimensions'!$C$45:$C$48,MATCH(N13,'T5 Other Dimensions'!$B$45:$B$48,0)),"?")} -> Road
A14: MR-1009 | B14: 46063 | C14: Gwadar Port | D14: Karachi Cantt | E14: Marine | F14: Delivered | G14: 17500 | H14: 98000 | J14: 20260212 | K14: 3 | L14: 4 | M14: 11 | N14: 3 | O14: 2 | P14: RD-511 | Q14: 5500 | R14: 36000 | S14: 1 | U14: {=IFERROR(INDEX('T4 DimCity'!$K$6:$K$20,MATCH(K14,'T4 DimCity'!$I$6:$I$20,0)),"?")} -> Sindh | V14: {=IFERROR(INDEX('T5 Other Dimensions'!$C$45:$C$48,MATCH(N14,'T5 Other Dimensions'!$B$45:$B$48,0)),"?")} -> Road
A15: MR-1010 | B15: 46064 | C15: Port Qasim | D15: Islamabad Dry Port | E15: Marine | F15: Delivered | G15: 15500 | H15: 139000 | J15: 20260206 | K15: 3 | L15: 8 | M15: 13 | N15: 3 | O15: 3 | P15: RD-506 | Q15: 7400 | R15: 83000 | S15: 1 | U15: {=IFERROR(INDEX('T4 DimCity'!$K$6:$K$20,MATCH(K15,'T4 DimCity'!$I$6:$I$20,0)),"?")} -> Sindh | V15: {=IFERROR(INDEX('T5 Other Dimensions'!$C$45:$C$48,MATCH(N15,'T5 Other Dimensions'!$B$45:$B$48,0)),"?")} -> Road
A16: MR-1011 | B16: 46065 | C16: Karachi Port | D16: Hyderabad | E16: Marine | F16: In Transit | G16: 13500 | H16: 61000 | J16: 20260210 | K16: 5 | L16: 6 | M16: 14 | N16: 3 | O16: 1 | P16: RD-509 | Q16: 6200 | R16: 44000 | S16: 1 | U16: {=IFERROR(INDEX('T4 DimCity'!$K$6:$K$20,MATCH(K16,'T4 DimCity'!$I$6:$I$20,0)),"?")} -> Punjab | V16: {=IFERROR(INDEX('T5 Other Dimensions'!$C$45:$C$48,MATCH(N16,'T5 Other Dimensions'!$B$45:$B$48,0)),"?")} -> Road
A17: MR-1012 | B17: 46066 | C17: Port Qasim | D17: Lahore Dry Port | E17: Marine | F17: Delivered | G17: 14000 | H17: 112000 | J17: 20260205 | K17: 2 | L17: 7 | M17: 16 | N17: 3 | O17: 1 | P17: RD-505 | Q17: 6100 | R17: 47000 | S17: 1 | U17: {=IFERROR(INDEX('T4 DimCity'!$K$6:$K$20,MATCH(K17,'T4 DimCity'!$I$6:$I$20,0)),"?")} -> Islamabad ICT | V17: {=IFERROR(INDEX('T5 Other Dimensions'!$C$45:$C$48,MATCH(N17,'T5 Other Dimensions'!$B$45:$B$48,0)),"?")} -> Road
... A39: RD-512 | B39: 46066 | C39: Rawalpindi | D39: Abbottabad | E39: Road | F39: Delivered | G39: 5800 | H39: 45000 | J39: 20260209 | K39: 3 | L39: 12 | M39: 20 | N39: 2 | O39: 3 | P39: RL-45018 | Q39: 27500 | R39: 289000 | S39: 1 | U39: {=IFERROR(INDEX('T4 DimCity'!$K$6:$K$20,MATCH(K39,'T4 DimCity'!$I$6:$I$20,0)),"?")} -> Sindh | V39: {=IFERROR(INDEX('T5 Other Dimensions'!$C$45:$C$48,MATCH(N39,'T5 Other Dimensions'!$B$45:$B$48,0)),"?")} -> Rail
P40: TOTAL | Q40: =SUM(Q6:Q39) -> 578650 | R40: =SUM(R6:R39) -> 4808000 | S40: =SUM(S6:S39) -> 34
A42: Columns U and V are a scratch pad, NOT part of the fact table. Excel has no relationships, so T7 needs the province and the mode name as text to build a matrix with SUMIFS. In Power BI the relationship does this for you and these two columns must not exist in your .pbix — if they do, you have put descriptive text back into a fact table and undone the whole exercise.
A44: THE THREE QUESTIONS THIS TASK IS REALLY ASKING
A45: Every lookup above is wrapped in IFERROR(…, -1) instead of being left to fail. Name what that buys you and what it costs you. | J45: What it buys you: It guarantees pipeline resilience. If a source file introduces a new location spelling or code that hasn't been added to the dimension table yet, the ETL process will not fail, crash, or drop the row. Instead, it safely maps the missing lookup to the reserved -1 Unknown surrogate key. What it costs you: It creates silent failures (data masking). Typos, dirty data, or missing dimension records are quietly swept under the -1 bucket. This hides data quality issues from engineers, meaning you won't get alerted that your dimension table needs updating.
A47: Columns C to F still hold the text. Why do they not cross the gap into the fact table? | J47: Architectural Principle: Fact tables store numeric measures (like WeightKG, CostPKR) and foreign surrogate keys (like OriginCityKey, DateKey), not descriptive text. Keeping descriptive attributes (such as city names, statuses, or modes) out of the fact table prevents massive data redundancy, reduces storage bloat, and ensures that text updates only need to happen in one place (the dimension tables).
A49: ShipmentID is in the fact table but joins to nothing. Defend keeping it. | J49: Degenerate Dimension: Even though ShipmentID does not join to a separate dimension table, keeping it in the fact table makes it a degenerate dimension. Why keep it: It provides unique business identification for every single shipment row, enabling auditing, row-level traceability back to source systems, and reliable drill-through capabilities without bloating the schema with an unnecessary dummy dimension table.
A52: Marking, 15 marks: six key columns correct 9 · measures and degenerate key 3 · the three questions 3. A hard-typed key column instead of a lookup scores zero for that column — the point is the join, not the digit.

Sheet T7 Reconcile
A1: T7 · Reconcile — Thirteen Checks, All Thirteen Must Pass
A2: The reshaping must not change a single kilogram. Reconciliation is not a formality: it is the last moment at which you can still find the mistake cheaply.
A4: # | B4: Check | C4: Expected | D4: Your result | E4: Pass? | F4: If it does not match, look here first
A5: 1 | B5: Row count of FactShipment | C5: 34 | D5: =COUNT('T6 FactShipment'!$J$6:$J$39) -> 34 | E5: =IF(D5=C5,"✔ pass","✘ fix") -> ✔ pass | F5: You dropped rows in a lookup, or you duplicated one to fit a dimension. A changed row count means the grain moved.
A6: 2 | B6: Grand total, WeightKG | C6: 578650 | D6: =SUM('T6 FactShipment'!$Q$6:$Q$39) -> 578650 | E6: =IF(D6=C6,"✔ pass","✘ fix") -> ✔ pass | F6: Rail is still in tonnes (a factor of 1,000 missing), or the rd-505 duplicate came back, or the Road TOTAL row survived staging.
A7: 3 | B7: Grand total, FreightCostPKR | C7: 4808000 | D7: =SUM('T6 FactShipment'!$R$6:$R$39) -> 4808000 | E7: =IF(D7=C7,"✔ pass","✘ fix") -> ✔ pass | F7: Same causes as the weight check. Costs are additive currency — there is no rounding excuse.
A8: 4 | B8: Shipment legs (SUM of Count) | C8: 34 | D8: =SUM('T6 FactShipment'!$S$6:$S$39) -> 34 | E8: =IF(D8=C8,"✔ pass","✘ fix") -> ✔ pass | F8: A measure problem, not a data problem — check that ShipmentCount is 1 on every row, including the last one.
A9: 5 | B9: Distinct ShipmentID values | C9: 34 | D9: =SUMPRODUCT(('T6 FactShipment'!$P$6:$P$39<>"")/COUNTIF('T6 FactShipment'!$P$6:$P$39,'T6 FactShipment'!$P$6:$P$39&"")) -> 34 | E9: =IF(D9=C9,"✔ pass","✘ fix") -> ✔ pass | F9: Equal to the leg count here because no consignment was split. The day they differ, the grain sentence has to say which one a row is.
A10: 6 | B10: Rows in DimCity (excluding Unknown) | C10: 14 | D10: =COUNTIF('T4 DimCity'!$I$6:$I$20,">0") -> 14 | E10: =IF(D10=C10,"✔ pass","✘ fix") -> ✔ pass | F10: Your conforming map is incomplete — you still have 23, or some number in between.
A11: 7 | B11: Rows in DimRoute (excluding Unknown) | C11: 20 | D11: =COUNTIF('T5 Other Dimensions'!$B$10:$B$30,">0") -> 20 | E11: =IF(D11=C11,"✔ pass","✘ fix") -> ✔ pass | F11: 30 means you deduplicated the raw strings instead of the conformed city keys. Go back to T5 Block A.
A12: 8 | B12: Rows in DimDate | C12: 28 | D12: =COUNTA('T5 Other Dimensions'!$C$53:$C$80) -> 28 | E12: =IF(D12=C12,"✔ pass","✘ fix") -> ✔ pass | F12: 12 means you generated only the dates that appear in the fact table. A date dimension with holes breaks every time-intelligence function.
A13: 9 | B13: WeightKG for Sindh / Marine | C13: 169000 | D13: =SUMIFS('T6 FactShipment'!$Q$6:$Q$39,'T6 FactShipment'!$U$6:$U$39,"Sindh",'T6 FactShipment'!$V$6:$V$39,"Marine") -> 169000 | E13: =IF(D13=C13,"✔ pass","✘ fix") -> ✔ pass | F13: If you got 206,500 you mapped Gwadar Port to Karachi. Gwadar is in Balochistan, and it is the one conforming decision students get wrong most often.
A14: 10 | B14: WeightKG for Punjab / Road | C14: 44100 | D14: =SUMIFS('T6 FactShipment'!$Q$6:$Q$39,'T6 FactShipment'!$U$6:$U$39,"Punjab",'T6 FactShipment'!$V$6:$V$39,"Road") -> 44100 | E14: =IF(D14=C14,"✔ pass","✘ fix") -> ✔ pass | F14: Check that Lahore, Faisalabad, Multan, Sialkot, Gujranwala and Rawalpindi all map to Punjab — and that Islamabad does NOT.
A15: 11 | B15: WeightKG for Sindh, all modes | C15: 484350 | D15: =SUMIFS('T6 FactShipment'!$Q$6:$Q$39,'T6 FactShipment'!$U$6:$U$39,"Sindh") -> 484350 | E15: =IF(D15=C15,"✔ pass","✘ fix") -> ✔ pass | F15: 83.7% of everything PakFreight moved. If it is lower, some Karachi alias is still its own city.
A16: 12 | B16: Fact rows pointing at an Unknown key (-1) | C16: 0 | D16: =COUNTIF('T6 FactShipment'!$K$6:$K$39,-1)+COUNTIF('T6 FactShipment'!$L$6:$L$39,-1)+COUNTIF('T6 FactShipment'!$M$6:$M$39,-1)+COUNTIF('T6 FactShipment'!$N$6:$N$39,-1)+COUNTIF('T6 FactShipment'!$O$6:$O$39,-1) -> 0 | E16: =IF(D16=C16,"✔ pass","✘ fix") -> ✔ pass | F16: A lookup failed and IFERROR caught it. Which column, and which row? The -1 row exists so this is a number you can read, not a row you lost.
A17: 13 | B17: Cost per KG, grand total | C17: 8.31 | D17: =SUM('T6 FactShipment'!$R$6:$R$39)/SUM('T6 FactShipment'!$Q$6:$Q$39) -> 8.3089951 | E17: =IF(ABS(D17-C17)<=0.005,"✔ pass","✘ fix") -> ✔ pass | F17: 8.06 means you averaged a ratio instead of dividing two sums. See T3 — this is the same 3% error, now wearing a dashboard.
B19: CHECKS PASSING | C19: =COUNTIF(E5:E17,"✔*")&" / 13" -> 13 / 13 | D19: =IF(COUNTIF(E5:E17,"✔*")=13,"✔ SUBMIT","✘ NOT YET") -> ✔ SUBMIT | F19: Submitting with a single red cell loses all 8 marks for this task. Thirteen out of thirteen, or it is not done.
A21: THE DELIVERABLE MATRIX · TONNAGE BY ORIGIN PROVINCE AND MODE
A22: Build this in Power BI too: Province on rows, Mode on columns, Total Weight KG in values. The grand total must read 578,650 kg exactly.
B23: Origin province | C23: Marine | D23: Rail | E23: Road | F23: Total
B24: Sindh | C24: =SUMIFS('T6 FactShipment'!$Q$6:$Q$39,'T6 FactShipment'!$U$6:$U$39,$B24,'T6 FactShipment'!$V$6:$V$39,"Marine") -> 169000 | D24: =SUMIFS('T6 FactShipment'!$Q$6:$Q$39,'T6 FactShipment'!$U$6:$U$39,$B24,'T6 FactShipment'!$V$6:$V$39,"Rail") -> 295250 | E24: =SUMIFS('T6 FactShipment'!$Q$6:$Q$39,'T6 FactShipment'!$U$6:$U$39,$B24,'T6 FactShipment'!$V$6:$V$39,"Road") -> 20100 | F24: =SUM(C24:E24) -> 484350
B25: Punjab | C25: =SUMIFS('T6 FactShipment'!$Q$6:$Q$39,'T6 FactShipment'!$U$6:$U$39,$B25,'T6 FactShipment'!$V$6:$V$39,"Marine") -> 0 | D25: =SUMIFS('T6 FactShipment'!$Q$6:$Q$39,'T6 FactShipment'!$U$6:$U$39,$B25,'T6 FactShipment'!$V$6:$V$39,"Rail") -> 0 | E25: =SUMIFS('T6 FactShipment'!$Q$6:$Q$39,'T6 FactShipment'!$U$6:$U$39,$B25,'T6 FactShipment'!$V$6:$V$39,"Road") -> 44100 | F25: =SUM(C25:E25) -> 44100
B26: Balochistan | C26: =SUMIFS('T6 FactShipment'!$Q$6:$Q$39,'T6 FactShipment'!$U$6:$U$39,$B26,'T6 FactShipment'!$V$6:$V$39,"Marine") -> 37500 | D26: =SUMIFS('T6 FactShipment'!$Q$6:$Q$39,'T6 FactShipment'!$U$6:$U$39,$B26,'T6 FactShipment'!$V$6:$V$39,"Rail") -> 0 | E26: =SUMIFS('T6 FactShipment'!$Q$6:$Q$39,'T6 FactShipment'!$U$6:$U$39,$B26,'T6 FactShipment'!$V$6:$V$39,"Road") -> 6600 | F26: =SUM(C26:E26) -> 44100
B27: Khyber Pakhtunkhwa | C27: =SUMIFS('T6 FactShipment'!$Q$6:$Q$39,'T6 FactShipment'!$U$6:$U$39,$B27,'T6 FactShipment'!$V$6:$V$39,"Marine") -> 0 | D27: =SUMIFS('T6 FactShipment'!$Q$6:$Q$39,'T6 FactShipment'!$U$6:$U$39,$B27,'T6 FactShipment'!$V$6:$V$39,"Rail") -> 0 | E27: =SUMIFS('T6 FactShipment'!$Q$6:$Q$39,'T6 FactShipment'!$U$6:$U$39,$B27,'T6 FactShipment'!$V$6:$V$39,"Road") -> 0 | F27: =SUM(C27:E27) -> 0
B28: Islamabad ICT | C28: =SUMIFS('T6 FactShipment'!$Q$6:$Q$39,'T6 FactShipment'!$U$6:$U$39,$B28,'T6 FactShipment'!$V$6:$V$39,"Marine") -> 0 | D28: =SUMIFS('T6 FactShipment'!$Q$6:$Q$39,'T6 FactShipment'!$U$6:$U$39,$B28,'T6 FactShipment'!$V$6:$V$39,"Rail") -> 0 | E28: =SUMIFS('T6 FactShipment'!$Q$6:$Q$39,'T6 FactShipment'!$U$6:$U$39,$B28,'T6 FactShipment'!$V$6:$V$39,"Road") -> 6100 | F28: =SUM(C28:E28) -> 6100
B29: Grand total | C29: =SUM(C24:C28) -> 206500 | D29: =SUM(D24:D28) -> 295250 | E29: =SUM(E24:E28) -> 76900 | F29: =SUM(F24:F28) -> 578650
B30: Reconciles to 578,650? | F30: =IF(F29=578650,"✔ pass","✘ fix") -> ✔ pass
A31: Read the Khyber Pakhtunkhwa row: zero. PakFreight moved 61,900 kg INTO Peshawar and Abbottabad in February and nothing out of them, and this matrix is built on OriginCityKey. The number is correct, and the conclusion a reader draws from it — 'KP is not part of our network' — is false. A role-playing dimension is exactly this: the same DimCity answers two different questions, and the active relationship silently decides which one you asked. Rebuild the matrix on DestCityKey and KP reads 61,900 kg. In Power BI that is the USERELATIONSHIP bonus on slide 47.
A33: THE LAST QUESTION · WRITE IT BEFORE YOU SUBMIT
A34: Every one of the thirteen checks above passes and your matrix totals 578,650 kg. In two or three lines: name one thing that could still be wrong with this model that no check on this sheet would ever catch. | C34: Even if all 13 checks pass and totals match, using the wrong foreign key relationship (such as grouping by OriginCityKey instead of DestCityKey) can completely misrepresent business activity. For instance, the matrix shows zero tonnage for Khyber Pakhtunkhwa because it only tracks shipments originating from there, hiding the 61,900 kg delivered into it. No math or row-count check can catch a misleading conclusion caused by answering the wrong business question with a role-playing dimension.
A38: Marking, 8 marks: thirteen checks passing 5 (all or nothing) · the matrix 1 · the last question 2.
